Workbook

Sheet README
B2: FRAZIYM — One Product, Many Tools | Opportunity Database
B4: What this file is
B5: Scored opportunity database for the FRAZIYM ecosystem: ONE subscription product that bundles 240+ micro-tools (including long-tail tools used <=1x/month), priced per user plan — never per-tool, never underpriced. Built from 7 research streams (2026-09-02) with URL-sourced evidence.
B7: The 247 rows
B8: 103 research-locked rows (from data-repair DR-*, e-commerce EC-*, devtools DV-*, weird-gold WG-* streams) + 144 long-tail catalog rows (GT-*, pattern-inherited E3, each pointing to its research parent). Every row = one tool/feature candidate for the platform.
B10: Evidence legend
B11: E1 = direct community complaint/thread found (highest confidence). E2 = verified product/pricing/docs fact. E3 = pattern-inferred hypothesis — validate before building. 79 E1 / 15 E2 / 153 E3.
B13: Scoring model (10 dims)
B14: Demand 20% | Pain 15% | Frequency 10% | Automation 15% | Monetization 10% | Distribution 10% | Competition 5% (high=low rivalry) | Infra-econ 5% | Ecosystem 5% | Defensibility 5%. Composite = weighted sum, 0-10.
B16: Platform roles
B17: HOOK = free acquisition surface (SEO traffic). GLUE = keeps users returning (daily utilities). PRO = paywall-worthy professional features. LTV = flagship high-value tools that justify the subscription on their own (e.g., bank-statement PDF->CSV replaces $49.95/mo DocuClipper).
B19: Tier fit
... B31: Prepared 2026-09-03 | Full sources: research/*.md + download/FRAZIYM_Research_Export_Phase1.md | Currency: USD

Sheet Opportunities
B2: All 247 Scored Opportunities (filterable)
B4: Rank | C4: ID | D4: Tool / Opportunity | E4: Zone | F4: Cluster | G4: Evidence | H4: Composite | I4: Demand | J4: Pain | K4: Freq | L4: Automation | M4: Monetize | N4: Distrib | O4: Comp* | P4: Infra | Q4: Eco | R4: Defen | S4: Role | T4: Tier | U4: Effort h | V4: Maint min/wk | W4: AI | X4: SEO query / parent | Y4: Problem (abridged)
B5: 1 | C5: DR-C3 | D5: Adobe Acrobat's subscription-only pricing outrages buyers who need occasional PDF editing/merging/forms. | E5: Data & Repair | F5: Data & File Repair | G5: E1 | H5: 8.2 | I5: 9 | J5: 7 | K5: 9 | L5: 10 | M5: 6 | N5: 9 | O5: 4.5 | P5: 9.5 | Q5: 9 | R5: 6 | S5: HOOK | T5: FREE | U5: 10 | V5: 10 | W5: N | Y5: Adobe Acrobat's subscription-only pricing outrages buyers who need occasional PDF editing/merging/forms.
B6: 2 | C6: DR-F1 | D6: Bookkeepers cannot import bank transactions from PDF statements — QuickBooks Online users beg for PDF→CSV/Q... | E6: Data & Repair | F6: Data & File Repair | G6: E1 | H6: 8.03 | I6: 8.5 | J6: 9.5 | K6: 7 | L6: 8.5 | M6: 9 | N6: 7 | O6: 6 | P6: 6.5 | Q6: 8 | R6: 6 | S6: LTV | T6: PRO | U6: 40 | V6: 45 | W6: Y | Y6: Bookkeepers cannot import bank transactions from PDF statements — QuickBooks Online users beg for PDF→CSV/QBO conversion and are desperate when banks close online history.
B7: 3 | C7: GT-PDF-extract-DR-C2 | D7: PDF Table Extractor to CSV (text-layer) | E7: Data & Repair | F7: Data & File Repair | G7: E3 | H7: 7.75 | I7: 9 | J7: 8 | K7: 5 | L7: 9 | M7: 7 | N7: 9 | O7: 6 | P7: 7 | Q7: 8 | R7: 5 | S7: LTV | T7: PRO | U7: 40 | V7: 10 | W7: N | X7: extract tables from pdf to csv | Y7: Long-tail tool instance: PDF Table Extractor to CSV (text-layer). Pattern-inherited pain evidence from DR-C2 cluster; ships as part of the mega-toolbox catalog (<=1 use/month tools included by directive).
B8: 4 | C8: DR-D2 | D8: One conversion job requires stitching 3-5 different single-purpose sites/tools; users lose track and hit ea... | E8: Data & Repair | F8: Data & File Repair | G8: E1 | H8: 7.67 | I8: 9 | J8: 8 | K8: 7 | L8: 8.5 | M8: 5 | N8: 8 | O8: 3.5 | P8: 9.5 | Q8: 10 | R8: 5 | S8: HOOK | T8: FREE | U8: 12 | V8: 10 | W8: N | Y8: One conversion job requires stitching 3-5 different single-purpose sites/tools; users lose track and hit each tool's free caps.
B9: 5 | C9: DR-B2 | D9: Multi-hundred-MB/GB JSON & JSONL files crash or freeze editors (VS Code 5MB JSON mode limit; 700MB jsonline... | E9: Data & Repair | F9: Data & File Repair | G9: E1 | H9: 7.62 | I9: 9 | J9: 8.5 | K9: 7 | L9: 8.5 | M9: 5 | N9: 9 | O9: 3.5 | P9: 9.5 | Q9: 4.5 | R9: 6 | S9: HOOK | T9: FREE | U9: 12 | V9: 10 | W9: N | Y9: Multi-hundred-MB/GB JSON & JSONL files crash or freeze editors (VS Code 5MB JSON mode limit; 700MB jsonlines crashes VS Code).
B10: 6 | C10: DR-H1 | D10: SMBs and individuals still spend hours monthly on manual invoice/receipt data entry and want any automation... | E10: Data & Repair | F10: Data & File Repair | G10: E1 | H10: 7.6 | I10: 8 | J10: 8 | K10: 9 | L10: 8.5 | M10: 7.5 | N10: 7 | O10: 6.5 | P10: 6 | Q10: 7 | R10: 4 | S10: LTV | T10: MAX | U10: 40 | V10: 45 | W10: Y | Y10: SMBs and individuals still spend hours monthly on manual invoice/receipt data entry and want any automation that actually works.
B11: 7 | C11: WG-G4 | D11: Hallucinated citations — verifying AI-generated references | E11: Education & Weird Gold | F11: Weird Gold / Education | G11: E1 | H11: 7.6 | I11: 8 | J11: 9.5 | K11: 6 | L11: 6.5 | M11: 7.5 | N11: 8 | O11: 9 | P11: 6 | Q11: 7 | R11: 7 | S11: LTV | T11: MAX | U11: 36 | V11: 30 | W11: N | Y11: Nature-linked analysis: "Tens of thousands of publications from 2025 might include invalid references generated by AI" (r/technology thread: https://www.reddit.com/r/technology/comments/1sd0khs/); study: ChatGPT false-citation rates 6%–60% by domain (https://w
B12: 8 | C12: GT-CSV-split-DR-B2 | D12: CSV Splitter (rows / file size) | E12: Data & Repair | F12: Data & File Repair | G12: E3 | H12: 7.6 | I12: 8 | J12: 8 | K12: 5 | L12: 10 | M12: 6 | N12: 9 | O12: 5 | P12: 10 | Q12: 7 | R12: 4 | S12: PRO | T12: PRO | U12: 8 | V12: 10 | W12: N | X12: split large csv files | Y12: Long-tail tool instance: CSV Splitter (rows / file size). Pattern-inherited pain evidence from DR-B2 cluster; ships as part of the mega-toolbox catalog (<=1 use/month tools included by directive).
B13: 9 | C13: GT-CSV-excel-DR-A2 | D13: Leading-Zero & Date Guard (CSV open protector) | E13: Data & Repair | F13: Data & File Repair | G13: E3 | H13: 7.6 | I13: 8 | J13: 8 | K13: 6 | L13: 10 | M13: 5 | N13: 9 | O13: 5 | P13: 10 | Q13: 7 | R13: 4 | S13: PRO | T13: PRO | U13: 10 | V13: 10 | W13: N | X13: excel removes leading zeros fix | Y13: Long-tail tool instance: Leading-Zero & Date Guard (CSV open protector). Pattern-inherited pain evidence from DR-A2 cluster; ships as part of the mega-toolbox catalog (<=1 use/month tools included by directive).
B14: 10 | C14: EC-C21 | D14: Manually matching bank/UPI payments to invoices/orders — sellers literally work out "which combinations of ... | E14: E-commerce & SMB | F14: E-commerce & SMB Ops | G14: E1 | H14: 7.58 | I14: 6.5 | J14: 9 | K14: 7 | L14: 8.5 | M14: 8 | N14: 7 | O14: 9 | P14: 6 | Q14: 8 | R14: 6 | S14: LTV | T14: PRO | U14: 12 | V14: 10 | W14: N | Y14: Manually matching bank/UPI payments to invoices/orders — sellers literally work out "which combinations of invoice amounts add up to each payment amount" on weekends; UPI/direct-transfer payments arrive with no references.
B15: 11 | C15: DV-B1 | D15: JSON viewers/editors crash or freeze on large (100MB–1GB+) JSON files, so devs fall back to command-line jq... | E15: DevTools & Data | F15: Developer Tools | G15: E1 | H15: 7.58 | I15: 7.5 | J15: 7 | K15: 7 | L15: 10 | M15: 6.5 | N15: 8 | O15: 6 | P15: 10 | Q15: 5.5 | R15: 6 | S15: PRO | T15: PRO | U15: 10 | V15: 10 | W15: N | X15: strong free-tool wedge with clear upgrade path (browser WASM = differentiator "file never leaves your machine"). | Y15: JSON viewers/editors crash or freeze on large (100MB–1GB+) JSON files, so devs fall back to command-line jq or buy specialized viewers.
B16: 12 | C16: DR-A2 | D16: CSVs open with all data in one column or split wrongly because the delimiter is comma vs semicolon (Europea... | E16: Data & Repair | F16: Data & File Repair | G16: E1 | H16: 7.55 | I16: 9 | J16: 8 | K16: 9 | L16: 8.5 | M16: 5 | N16: 9 | O16: 3.5 | P16: 7.5 | Q16: 4.5 | R16: 4 | S16: HOOK | T16: FREE | U16: 12 | V16: 10 | W16: N | Y16: CSVs open with all data in one column or split wrongly because the delimiter is comma vs semicolon (European locale) or SEP= line missing.
B17: 13 | C17: EC-C28 | D17: (Developing-market angle, partially inferred) Bangladesh/South-Asia micro-sellers keep records in manual kh... | E17: E-commerce & SMB | F17: E-commerce & SMB Ops | G17: E2 | H17: 7.55 | I17: 8 | J17: 7 | K17: 9 | L17: 8.5 | M17: 6 | N17: 8 | O17: 8.5 | P17: 7.5 | Q17: 4.5 | R17: 6 | S17: HOOK | T17: FREE | U17: 12 | V17: 10 | W17: N | Y17: (Developing-market angle, partially inferred) Bangladesh/South-Asia micro-sellers keep records in manual khata notebooks or Excel; local-language/local-format accounting software is thin; bKash/wallet payment trails live in SMS and screenshots, not ledgers.
B18: 14 | C18: EC-C29 | D18: WhatsApp-order chaos: sellers take 20–30 orders/day as chat messages; tracking in notebook/Excel/memory; no... | E18: E-commerce & SMB | F18: E-commerce & SMB Ops | G18: E1 | H18: 7.55 | I18: 7.5 | J18: 8.5 | K18: 9 | L18: 8.5 | M18: 7 | N18: 5 | O18: 8.5 | P18: 7.5 | Q18: 8 | R18: 4 | S18: LTV | T18: PRO | U18: 12 | V18: 10 | W18: N | Y18: WhatsApp-order chaos: sellers take 20–30 orders/day as chat messages; tracking in notebook/Excel/memory; no order numbers, missed orders, no payment status.
B19: 15 | C19: WG-G5 | D19: AI-detector false positives — students need a provenance trail | E19: Education & Weird Gold | F19: Weird Gold / Education | G19: E1 | H19: 7.55 | I19: 8.5 | J19: 9.5 | K19: 8 | L19: 6.5 | M19: 6.5 | N19: 6.5 | O19: 8.5 | P19: 7.5 | Q19: 7 | R19: 4 | S19: PRO | T19: PRO | U19: 36 | V19: 30 | W19: N | Y19: r/Teachers: "False positives from AI detection in education destroyed my [relationship with students]... One of them cried in my office" (https://www.reddit.com/r/Teachers/comments/1oqozxw/); districts face lawsuits over false accusations (https://www.reddit.c
B20: 16 | C20: EC-C3 | D20: Shopify rejects CSVs for invisible format reasons: non-UTF-8 encoding, illegal characters, wrong quoting — ... | E20: E-commerce & SMB | F20: E-commerce & SMB Ops | G20: E1 | H20: 7.53 | I20: 7.5 | J20: 8 | K20: 9 | L20: 10 | M20: 6.5 | N20: 8 | O20: 5 | P20: 6 | Q20: 4.5 | R20: 4 | S20: PRO | T20: PRO | U20: 10 | V20: 10 | W20: N | Y20: Shopify rejects CSVs for invisible format reasons: non-UTF-8 encoding, illegal characters, wrong quoting — error messages are cryptic.
B21: 17 | C21: DV-B3 | D21: CORS errors remain a top chronic frustration — devs don't understand why requests fail and the error masks ... | E21: DevTools & Data | F21: Developer Tools | G21: E1 | H21: 7.53 | I21: 9 | J21: 8 | K21: 9 | L21: 8 | M21: 4.5 | N21: 9 | O21: 5 | P21: 6 | Q21: 8 | R21: 2.5 | S21: HOOK | T21: FREE | U21: 12 | V21: 10 | W21: N | X21: huge traffic pool; monetize via related dev-tool bundle rather than the checker itself. | Y21: CORS errors remain a top chronic frustration — devs don't understand why requests fail and the error masks the real problem.
B22: 18 | C22: DR-C4 | D22: Filled PDF form data disappears when printing/emailing/saving (form fields not flattened), and users don't ... | E22: Data & Repair | F22: Data & File Repair | G22: E1 | H22: 7.48 | I22: 7 | J22: 7.5 | K22: 7 | L22: 10 | M22: 6.5 | N22: 7 | O22: 5.5 | P22: 9.5 | Q22: 7 | R22: 6 | S22: PRO | T22: PRO | U22: 10 | V22: 10 | W22: N | Y22: Filled PDF form data disappears when printing/emailing/saving (form fields not flattened), and users don't know the term or the fix.
B23: 19 | C23: EC-C26 | D23: Bank-statement PDF→CSV: bookkeepers refuse "shady websites that claim to convert while also storing the dat... | E23: E-commerce & SMB | F23: E-commerce & SMB Ops | G23: E1 | H23: 7.42 | I23: 9.5 | J23: 8 | K23: 7 | L23: 8.5 | M23: 6 | N23: 5 | O23: 5 | P23: 9.5 | Q23: 4.5 | R23: 6 | S23: GLUE | T23: FREE | U23: 12 | V23: 10 | W23: N | Y23: Bank-statement PDF→CSV: bookkeepers refuse "shady websites that claim to convert while also storing the data" — trust/privacy is the wedge (complements task 2-a's price-umbrella finding: DocuClipper ~$49.95/mo, MoneyThumb ~$299.95).
B24: 20 | C24: DR-C2 | D24: Scanned PDFs have no text layer / OCR errors — users can't search, copy, or correct the text. | E24: Data & Repair | F24: Data & File Repair | G24: E1 | H24: 7.4 | I24: 8.5 | J24: 8 | K24: 9 | L24: 8.5 | M24: 6.5 | N24: 7 | O24: 6 | P24: 5 | Q24: 4.5 | R24: 4 | S24: PRO | T24: PRO | U24: 40 | V24: 45 | W24: Y | Y24: Scanned PDFs have no text layer / OCR errors — users can't search, copy, or correct the text.
B25: 21 | C25: DR-D1 | D25: Users are now *afraid* of free online converters — FBI + Malwarebytes confirm converter sites push malware/... | E25: Data & Repair | F25: Data & File Repair | G25: E1 | H25: 7.4 | I25: 8 | J25: 7 | K25: 5 | L25: 8.5 | M25: 6 | N25: 8 | O25: 5 | P25: 9.5 | Q25: 9 | R25: 8 | S25: HOOK | T25: FREE | U25: 12 | V25: 10 | W25: N | Y25: Users are now *afraid* of free online converters — FBI + Malwarebytes confirm converter sites push malware/ransomware; privacy of sensitive docs is the blocker.
B26: 22 | C26: DV-B10 | D26: MySQL→PostgreSQL (and reverse) migrations require manual SQL dialect rewrites — type mappings, quote styles... | E26: DevTools & Data | F26: Developer Tools | G26: E1 | H26: 7.4 | I26: 6.5 | J26: 8 | K26: 8 | L26: 8 | M26: 8 | N26: 8 | O26: 6.5 | P26: 9 | Q26: 4.5 | R26: 6 | S26: LTV | T26: PRO | U26: 12 | V26: 10 | W26: N | X26: paying audience + client-side feasible = strong rev-max candidate; correctness must be excellent. | Y26: MySQL→PostgreSQL (and reverse) migrations require manual SQL dialect rewrites — type mappings, quote styles, function differences — and simple converter tools are asked for repeatedly.
B27: 23 | C27: GT-JSON-json-DV-B2 | D27: JSON to CSV (flatten, arrays-safe) | E27: DevTools & Data | F27: Developer Tools | G27: E3 | H27: 7.4 | I27: 8 | J27: 6 | K27: 7 | L27: 10 | M27: 5 | N27: 9 | O27: 4 | P27: 10 | Q27: 8 | R27: 4 | S27: PRO | T27: PRO | U27: 12 | V27: 10 | W27: N | X27: json to csv converter | Y27: Long-tail tool instance: JSON to CSV (flatten, arrays-safe). Pattern-inherited pain evidence from DV-B2 cluster; ships as part of the mega-toolbox catalog (<=1 use/month tools included by directive).
B28: 24 | C28: GT-CSV-csv-DR-A1-2 | D28: Universal CSV Pre-flight Validator | E28: Data & Repair | F28: Data & File Repair | G28: E3 | H28: 7.4 | I28: 7 | J28: 6 | K28: 6 | L28: 10 | M28: 6 | N28: 9 | O28: 6 | P28: 10 | Q28: 9 | R28: 5 | S28: PRO | T28: PRO | U28: 18 | V28: 10 | W28: N | X28: csv validator online | Y28: Long-tail tool instance: Universal CSV Pre-flight Validator. Pattern-inherited pain evidence from DR-A1 cluster; ships as part of the mega-toolbox catalog (<=1 use/month tools included by directive).
B29: 25 | C29: GT-MKT-shopify-EC-C1 | D29: Shopify Product CSV Pre-flight Validator | E29: E-commerce & SMB | F29: E-commerce & SMB Ops | G29: E3 | H29: 7.4 | I29: 7 | J29: 8 | K29: 5 | L29: 9 | M29: 7 | N29: 9 | O29: 6 | P29: 8 | Q29: 8 | R29: 5 | S29: LTV | T29: PRO | U29: 30 | V29: 25 | W29: Y | X29: shopify csv import errors | Y29: Long-tail tool instance: Shopify Product CSV Pre-flight Validator. Pattern-inherited pain evidence from EC-C1 cluster; ships as part of the mega-toolbox catalog (<=1 use/month tools included by directive).
B30: 26 | C30: DR-F2 | D30: CSV→QBO/OFX conversions fail validator checks (bank IDs, dates, amounts) and accounting software silently r... | E30: Data & Repair | F30: Data & File Repair | G30: E1 | H30: 7.35 | I30: 7 | J30: 8.5 | K30: 7 | L30: 8.5 | M30: 8 | N30: 7.5 | O30: 3.5 | P30: 7.5 | Q30: 8 | R30: 4 | S30: PRO | T30: PRO | U30: 12 | V30: 10 | W30: N | Y30: CSV→QBO/OFX conversions fail validator checks (bank IDs, dates, amounts) and accounting software silently rejects or duplicates imports.
B31: 27 | C31: DR-F4 | D31: Banks simply don't offer CSV/data downloads for business accounts — statements are PDF-only — so conversion... | E31: Data & Repair | F31: Data & File Repair | G31: E1 | H31: 7.35 | I31: 8 | J31: 8.5 | K31: 4 | L31: 8.5 | M31: 8.5 | N31: 7 | O31: 7 | P31: 6 | Q31: 8 | R31: 4 | S31: LTV | T31: MAX | U31: 40 | V31: 45 | W31: Y | Y31: Banks simply don't offer CSV/data downloads for business accounts — statements are PDF-only — so conversion is forced on every bookkeeper.
B32: 28 | C32: DR-A1 | D32: Excel silently truncates/mangles big CSVs and strips leading zeros + rewrites dates, so re-imports into oth... | E32: Data & Repair | F32: Data & File Repair | G32: E1 | H32: 7.33 | I32: 9.5 | J32: 7 | K32: 9 | L32: 8.5 | M32: 6 | N32: 7 | O32: 3.5 | P32: 6 | Q32: 4.5 | R32: 4 | S32: GLUE | T32: FREE | U32: 12 | V32: 10 | W32: N | Y32: Excel silently truncates/mangles big CSVs and strips leading zeros + rewrites dates, so re-imports into other systems fail.
B33: 29 | C33: DV-B6 | D33: Postman gutted its free plan (Feb–Mar 2026: 1 user only, collaboration features removed, $14/mo/member) — a... | E33: DevTools & Data | F33: Developer Tools | G33: E1 | H33: 7.3 | I33: 8 | J33: 8 | K33: 4.5 | L33: 8.5 | M33: 6 | N33: 9 | O33: 6 | P33: 7.5 | Q33: 8 | R33: 4 | S33: HOOK | T33: FREE | U33: 12 | V33: 10 | W33: N | X33: build SMALL wedge not full client: "paste curl → get shareable request + response inspector, no install". Timeliness flagged. | Y33: Postman gutted its free plan (Feb–Mar 2026: 1 user only, collaboration features removed, $14/mo/member) — active anger window and migration search traffic.
B34: 30 | C34: GT-CSV-csv-DR-A1 | D34: CSV Delimiter Fixer | E34: Data & Repair | F34: Data & File Repair | G34: E3 | H34: 7.3 | I34: 7 | J34: 7 | K34: 6 | L34: 10 | M34: 5 | N34: 9 | O34: 5 | P34: 10 | Q34: 8 | R34: 4 | S34: PRO | T34: PRO | U34: 8 | V34: 10 | W34: N | X34: csv wrong delimiter fix | Y34: Long-tail tool instance: CSV Delimiter Fixer. Pattern-inherited pain evidence from DR-A1 cluster; ships as part of the mega-toolbox catalog (<=1 use/month tools included by directive).
B35: 31 | C35: DR-B1 | D35: LLM-generated and human-edited JSON breaks parsers on trailing commas, single quotes, comments, unquoted ke... | E35: Data & Repair | F35: Data & File Repair | G35: E1 | H35: 7.25 | I35: 8.5 | J35: 6 | K35: 9 | L35: 8.5 | M35: 5 | N35: 8 | O35: 3.5 | P35: 9.5 | Q35: 4.5 | R35: 6 | S35: HOOK | T35: FREE | U35: 12 | V35: 10 | W35: N | Y35: LLM-generated and human-edited JSON breaks parsers on trailing commas, single quotes, comments, unquoted keys — users hunt the offending char manually.
B36: 32 | C36: DR-C1 | D36: PDF→Excel conversion scrambles tables (merged cells, no grid lines, spanning headers) and users spend hours... | E36: Data & Repair | F36: Data & File Repair | G36: E1 | H36: 7.25 | I36: 9 | J36: 8.5 | K36: 9 | L36: 5.5 | M36: 7 | N36: 8.5 | O36: 3.5 | P36: 6 | Q36: 4.5 | R36: 4 | S36: PRO | T36: MAX | U36: 52 | V36: 45 | W36: Y | Y36: PDF→Excel conversion scrambles tables (merged cells, no grid lines, spanning headers) and users spend hours cleaning.
B37: 33 | C37: GT-CSV-find-DR-F1 | D37: Duplicate Row Finder (exact + fuzzy) | E37: Data & Repair | F37: Data & File Repair | G37: E3 | H37: 7.25 | I37: 7 | J37: 7 | K37: 5 | L37: 10 | M37: 6 | N37: 8 | O37: 6 | P37: 10 | Q37: 7 | R37: 5 | S37: PRO | T37: PRO | U37: 14 | V37: 10 | W37: N | X37: find duplicate rows csv | Y37: Long-tail tool instance: Duplicate Row Finder (exact + fuzzy). Pattern-inherited pain evidence from DR-F1 cluster; ships as part of the mega-toolbox catalog (<=1 use/month tools included by directive).
B38: 34 | C38: DR-A5 | D38: Marketplace/platform CSV imports (Shopify) fail on supplier CSVs because quoting, encoding, and column orde... | E38: Data & Repair | F38: Data & File Repair | G38: E1 | H38: 7.22 | I38: 7.5 | J38: 8 | K38: 7 | L38: 8.5 | M38: 8 | N38: 7 | O38: 5 | P38: 7.5 | Q38: 4.5 | R38: 4 | S38: PRO | T38: PRO | U38: 12 | V38: 10 | W38: N | Y38: Marketplace/platform CSV imports (Shopify) fail on supplier CSVs because quoting, encoding, and column order don't match Shopify's template.
B39: 35 | C39: EC-C1 | D39: "Supplier CSV import hell" — every supplier catalog update requires hours of manual fixing before Shopify a... | E39: E-commerce & SMB | F39: E-commerce & SMB Ops | G39: E1 | H39: 7.17 | I39: 7.5 | J39: 8.5 | K39: 7 | L39: 8 | M39: 7.5 | N39: 8.5 | O39: 3.5 | P39: 6 | Q39: 4.5 | R39: 4 | S39: PRO | T39: PRO | U39: 12 | V39: 10 | W39: N | Y39: "Supplier CSV import hell" — every supplier catalog update requires hours of manual fixing before Shopify accepts it: merged columns, wrong headers, images not importing, variants scrambled, "illegal quoting" errors.
B40: 36 | C40: DR-A6 | D40: Files >1M rows can't be opened in Excel — users need to split huge CSVs and don't know how. | E40: Data & Repair | F40: Data & File Repair | G40: E1 | H40: 7.15 | I40: 7.5 | J40: 7 | K40: 7 | L40: 10 | M40: 6 | N40: 7 | O40: 3.5 | P40: 7.5 | Q40: 7 | R40: 4 | S40: GLUE | T40: FREE | U40: 10 | V40: 10 | W40: N | Y40: Files >1M rows can't be opened in Excel — users need to split huge CSVs and don't know how.
B41: 37 | C41: EC-C7 | D41: Multichannel inventory sync (Shopify+Etsy+eBay+Amazon+POS) for tiny sellers = overselling risk; enterprise ... | E41: E-commerce & SMB | F41: E-commerce & SMB Ops | G41: E1 | H41: 7.15 | I41: 6.5 | J41: 8 | K41: 9 | L41: 8.5 | M41: 7 | N41: 7 | O41: 5.5 | P41: 7.5 | Q41: 4.5 | R41: 4 | S41: PRO | T41: PRO | U41: 12 | V41: 10 | W41: N | Y41: Multichannel inventory sync (Shopify+Etsy+eBay+Amazon+POS) for tiny sellers = overselling risk; enterprise sync tools are overkill/too pricey, so sellers juggle spreadsheets.
B42: 38 | C42: GT-JSON-fix-DV-B20 | D42: JSON Repair / Error Fixer | E42: DevTools & Data | F42: Developer Tools | G42: E3 | H42: 7.15 | I42: 7 | J42: 7 | K42: 6 | L42: 10 | M42: 5 | N42: 8 | O42: 5 | P42: 10 | Q42: 7 | R42: 4 | S42: PRO | T42: PRO | U42: 10 | V42: 25 | W42: Y | X42: fix invalid json online | Y42: Long-tail tool instance: JSON Repair / Error Fixer. Pattern-inherited pain evidence from DV-B20 cluster; ships as part of the mega-toolbox catalog (<=1 use/month tools included by directive).
...

Sheet Top 50
B2: Top 50 Opportunities by Composite Score
B4: Rank | C4: ID | D4: Tool / Opportunity | E4: Zone | F4: Score | G4: Role | H4: Tier | I4: Why it wins (abridged) | J4: Existing tools / price anchors | K4: Src URLs
B5: 1 | C5: DR-C3 | D5: Adobe Acrobat's subscription-only pricing outrages buyers who need occasional PDF editing/merging/forms. | E5: Data & Repair | F5: 8.2 | G5: HOOK | H5: FREE | I5: Adobe Acrobat's subscription-only pricing outrages buyers who need occasional PDF editing/merging/forms. | J5: iLovePDF (free tier w/ file-size caps; Premium $5/mo annual, $9/mo monthly — ilovepdf.com/pricing), Smallpdf (free 2 tasks/day-ish trial behavior; Pro $12/mo or $108/yr — ihatepdf comparison + smallpdf pricing page), PDF | K5: 4
B6: 2 | C6: DR-F1 | D6: Bookkeepers cannot import bank transactions from PDF statements — QuickBooks Online users beg for PDF→CSV/Q... | E6: Data & Repair | F6: 8.03 | G6: LTV | H6: PRO | I6: Bookkeepers cannot import bank transactions from PDF statements — QuickBooks Online users beg for PDF→CSV/QBO conversion and are desperate when banks close online history. | J6: DocuClipper (from $39.95-$49.95/mo for 20 conversions per docuclipper blog — verified on their blog), MoneyThumb 2qbo Convert Pro+ ($299.95 — capyparse review), ProperSoft ProperConvert (desktop, one-time, price on purch | K6: 3
B7: 3 | C7: GT-PDF-extract-DR-C2 | D7: PDF Table Extractor to CSV (text-layer) | E7: Data & Repair | F7: 7.75 | G7: LTV | H7: PRO | I7: Long-tail tool instance: PDF Table Extractor to CSV (text-layer). Pattern-inherited pain evidence from DR-C2 cluster; ships as part of the mega-toolbox catalog (<=1 use/month tools included by directive). | J7: Inherits demand pattern from research row DR-C2 (see DR-C2 for E1/E2 evidence). | K7: 0
B8: 4 | C8: DR-D2 | D8: One conversion job requires stitching 3-5 different single-purpose sites/tools; users lose track and hit ea... | E8: Data & Repair | F8: 7.67 | G8: HOOK | H8: FREE | I8: One conversion job requires stitching 3-5 different single-purpose sites/tools; users lose track and hit each tool's free caps. | J8: iLovePDF (free caps, Premium $5/mo annual per pricing page), Smallpdf (Pro $12/mo, $108/yr), Adobe online. | K8: 4
B9: 5 | C9: DR-B2 | D9: Multi-hundred-MB/GB JSON & JSONL files crash or freeze editors (VS Code 5MB JSON mode limit; 700MB jsonline... | E9: Data & Repair | F9: 7.62 | G9: HOOK | H9: FREE | I9: Multi-hundred-MB/GB JSON & JSONL files crash or freeze editors (VS Code 5MB JSON mode limit; 700MB jsonlines crashes VS Code). | J9: Dadroit (free viewer, commercial product), Janice (free desktop), jq (free CLI). | K9: 3
B10: 6 | C10: DR-H1 | D10: SMBs and individuals still spend hours monthly on manual invoice/receipt data entry and want any automation... | E10: Data & Repair | F10: 7.6 | G10: LTV | H10: MAX | I10: SMBs and individuals still spend hours monthly on manual invoice/receipt data entry and want any automation that actually works. | J10: Expensify (freemium, price unverified), Dext (paid, unverified), DIY OCR scripts. | K10: 4
B11: 7 | C11: WG-G4 | D11: Hallucinated citations — verifying AI-generated references | E11: Education & Weird Gold | F11: 7.6 | G11: LTV | H11: MAX | I11: Nature-linked analysis: "Tens of thousands of publications from 2025 might include invalid references generated by AI" (r/technology thread: https://www.reddit.com/r/technology/comments/1sd0khs/); study: ChatGPT false-citation rates 6%–60% by domain (https://www.psypost.org/chatgpt-hallucinates-fake | J11: Sourcely et al. push paid "verify sources" SaaS (https://www.sourcely.net/resources/ai-hallucinated-citations-spot-fake-sources-before-submit); no dominant free batch-verifier found in results. | K11: 6
B12: 8 | C12: GT-CSV-split-DR-B2 | D12: CSV Splitter (rows / file size) | E12: Data & Repair | F12: 7.6 | G12: PRO | H12: PRO | I12: Long-tail tool instance: CSV Splitter (rows / file size). Pattern-inherited pain evidence from DR-B2 cluster; ships as part of the mega-toolbox catalog (<=1 use/month tools included by directive). | J12: Inherits demand pattern from research row DR-B2 (see DR-B2 for E1/E2 evidence). | K12: 0
B13: 9 | C13: GT-CSV-excel-DR-A2 | D13: Leading-Zero & Date Guard (CSV open protector) | E13: Data & Repair | F13: 7.6 | G13: PRO | H13: PRO | I13: Long-tail tool instance: Leading-Zero & Date Guard (CSV open protector). Pattern-inherited pain evidence from DR-A2 cluster; ships as part of the mega-toolbox catalog (<=1 use/month tools included by directive). | J13: Inherits demand pattern from research row DR-A2 (see DR-A2 for E1/E2 evidence). | K13: 0
B14: 10 | C14: EC-C21 | D14: Manually matching bank/UPI payments to invoices/orders — sellers literally work out "which combinations of ... | E14: E-commerce & SMB | F14: 7.58 | G14: LTV | H14: PRO | I14: Manually matching bank/UPI payments to invoices/orders — sellers literally work out "which combinations of invoice amounts add up to each payment amount" on weekends; UPI/direct-transfer payments arrive with no references. | J14: accounting suites assume bank-feed auto-match (needs QBO/Xero + connected bank — unavailable for UPI/BD bank setups). | K14: 3
B15: 11 | C15: DV-B1 | D15: JSON viewers/editors crash or freeze on large (100MB–1GB+) JSON files, so devs fall back to command-line jq... | E15: DevTools & Data | F15: 7.58 | G15: PRO | H15: PRO | I15: JSON viewers/editors crash or freeze on large (100MB–1GB+) JSON files, so devs fall back to command-line jq or buy specialized viewers. | J15: Dadroit (commercial, price unverified), UltraEdit, jq (free CLI). | K15: 2
B16: 12 | C16: DR-A2 | D16: CSVs open with all data in one column or split wrongly because the delimiter is comma vs semicolon (Europea... | E16: Data & Repair | F16: 7.55 | G16: HOOK | H16: FREE | I16: CSVs open with all data in one column or split wrongly because the delimiter is comma vs semicolon (European locale) or SEP= line missing. | J16: Excel wizard, LibreOffice (free), many delimiter-converter web tools (unverified). | K16: 2
... B54: 50 | C54: EC-C15 | D54: Google Merchant Center disapprovals spike suddenly and in bulk: price-mismatch, missing GTIN, misclassified... | E54: E-commerce & SMB | F54: 7.03 | G54: LTV | H54: PRO | I54: Google Merchant Center disapprovals spike suddenly and in bulk: price-mismatch, missing GTIN, misclassified policy flags (e.g., 530 products flagged "Alcoholic drinks" wrongly); fixes require per-attribute edits across the feed. | J54: DataFeedWatch from ~$59–64/mo (F6); feed tools price out micro-sellers. | K54: 5

Sheet Clusters
B2: Zone-Level Portfolio Statistics
B4: Zone | C4: Tools | D4: Avg score | E4: Max score | F4: LTV | G4: PRO | H4: HOOK | I4: GLUE | J4: E1 rows | K4: E2 rows | L4: Build effort h | M4: Maint min/wk
B5: Data & Repair | C5: 60 | D5: 6.87 | E5: 8.2 | F5: 10 | G5: 18 | H5: 15 | I5: 17 | J5: 26 | K5: 1 | L5: 946 | M5: 845
B6: E-commerce & SMB | C6: 52 | D6: 6.44 | E6: 7.58 | F6: 14 | G6: 19 | H6: 2 | I6: 17 | J6: 30 | K6: 1 | L6: 858 | M6: 710
B7: DevTools & Data | C7: 55 | D7: 6.23 | E7: 7.58 | F7: 3 | G7: 11 | H7: 14 | I7: 27 | J7: 9 | K7: 7 | L7: 837 | M7: 805
B8: BD & Telegram | C8: 4 | D8: 6.09 | E8: 6.9 | F8: 2 | G8: 1 | H8: 0 | I8: 1 | J8: 0 | K8: 0 | L8: 133 | M8: 100
B9: Education & Weird Gold | C9: 48 | D9: 5.94 | E9: 7.6 | F9: 3 | G9: 14 | H9: 7 | I9: 24 | J9: 14 | K9: 6 | L9: 1488 | M9: 1355
B10: Media & Image | C10: 7 | D10: 5.87 | E10: 6.75 | F10: 0 | G10: 1 | H10: 4 | I10: 2 | J10: 0 | K10: 0 | L10: 102 | M10: 70
B11: Web & Text Utilities | C11: 21 | D11: 5.77 | E11: 6.6 | F11: 0 | G11: 1 | H11: 11 | I11: 9 | J11: 0 | K11: 0 | L11: 128 | M11: 210
B12: TOTAL | C12: 247 | D12: 6.32 | E12: 8.2 | F12: 32 | G12: 65 | H12: 53 | I12: 97 | J12: 79 | K12: 15 | L12: 4492 | M12: 4095
B14: Avg score column = mean composite per zone. Build effort = cumulative one-time build hours estimate (maint min/wk = recurring). Zones ordered by average score.

Sheet Pricing Model
B2: Subscription Model — One Product, Many Tools (anti-underpricing)
B4: Tier | C4: Price | D4: Annual | E4: Who it serves | F4: Limits & unlockables | G4: Platform roles served | H4: Value anchor (what it replaces) | I4: Why price is fair
B5: FREE | C5: $0 | D5: $0 | E5: Anyone arriving from search; students; casual one-off users | F5: All client-side tools unlimited; server/AI tools metered daily (10 credits); watermark/credit on shareable outputs; 1 concurrent job | G5: HOOK (53) + GLUE core (97) | H5: free alternatives: iLovePDF free, crontab.guru, jwt.io | I5: Free tier is the SEO engine: every tool page = a landing page; converts via caps + batch needs
B6: PRO | C6: $4.99/mo | D6: $39/yr | E6: Sellers, freelancers, students, office workers (the 95% case) | F6: Full 240+ toolbox; batch mode; no watermarks; 300 server credits/mo; 2GB files; priority queue | G6: PRO (65) + heavy GLUE | H6: iLovePDF ~$4-7/mo for PDF-only; Smallpdf $9/mo; Matrixify $20/mo for Shopify-only | I6: One niche incumbent charges more than PRO for ONE domain; FRAZIYM covers data+PDF+e-com+dev in one
B7: STUDIO | C7: $9.99/mo | D7: $79/yr | E7: Power users: accountants, agencies, AI-native devs | F7: PRO + AI-featured tools (1,500 AI credits/mo): citation verifier, error decoder, quiz/show-notes gen; API-lite 1k calls/mo; Telegram Mini App perks | G7: LTV (32) AI-assisted | H7: DocuClipper $49.95/mo (bank stmt only); Dext $13-20.50/mo (receipts only); DataFeedWatch $59/mo (feeds only) | I7: STUDIO replaces any ONE niche subscription at <25% of its price while including everything else
B8: MAX | C8: $19.99/mo | D8: $159/yr | E8: Small teams (3 seats), integrators, automation-heavy users | F8: STUDIO x3 seats + 5,000 AI credits + webhook workspace (bins/replay) + MCP tooling + 25k API calls + priority support | G8: LTV server-side + teams | H8: Postman $14/user/mo (1 user!); Hookdeck from ~$19/mo; ngrok $8-10/mo | I8: 3-seat team plan beats Postman single-user price; metered server features protected by caps
B10: Profit mechanics
B12: Infra cost | C12: $0 | D12: Cloudflare free tier (Workers 100k req/day, Pages, D1, R2, Queues, Cron) — verified 2026-09-02
B13: AI cost | C13: $0 | D13: Multi-provider free gateway: Groq + OpenRouter:free + CF Workers AI + SambaNova + Mistral ≈ 500-2,000 req/day pooled; cache-first routing
B14: Payment fees | C14: ~2-5% | D14: USDT P2P->bKash ≈1.4-2% (cheapest); Telegram Stars ≈4-5% (21-day hold); Paddle 5%+$1 when scale requires
B15: Gross margin | C15: ≈95-98% | D15: Revenue minus payment fees only; no hosting/AI fixed cost under free caps
B16: Underpricing guard | C16: Rule | D16: Any tier price change must stay above: (a) 2x cheapest single-niche competitor monthly price ÷ 20, (b) willingness-to-pay evidence floor $4/mo; never compete to $0
B18: Prices in USD. Stars/crypto rails avoid the Stripe/PayPal wall for a Bangladesh solo founder (see Payment Rails sheet). Prices intentionally at market-mid of consumer utility SaaS, not race-to-bottom.

Sheet Revenue Scenarios
B2: Revenue Scenarios — subscriber math (fees net of infra $0)
B4: Tier price assumptions (editable)
B6: PRO $/mo | C6: 4.99
B7: STUDIO $/mo | C7: 9.99
B8: MAX $/mo | C8: 19.99
B9: Ads+affiliate $/day (conservative) | C9: 0
B11: Scenarios (live formulas)
B12: Scenario | C12: PRO subs | D12: STUDIO subs | E12: MAX subs | F12: MRR $ | G12: $/day | H12: Fees ~% | I12: Net $/day | J12: Funnel assumption (E3) | K12: Trigger date (90-day plan) | L12: Cumulative tools live
B13: A — First blood | C13: 1 | D13: 0 | E13: 0 | F13: =C13*C6+D13*C7+E13*C8 -> 4.99 | G13: =F13*12/365 -> 0.16405479 | H13: 2 | I13: =G13*(1-H13/100)+C9 -> 0.1607737 | J13: Day 21-45: first paid conversion from one seeded tool's thank-you page | K13: Day 30: 6 tools | L13: 6
B14: B — $1/day | C14: 3 | D14: 1 | E14: 0 | F14: =C14*C6+D14*C7+E14*C8 -> 24.96 | G14: =F14*12/365 -> 0.82060274 | H14: 2.5 | I14: =G14*(1-H14/100)+C9 -> 0.80008767 | J14: 400-800 free-tool visits/day converting 0.5-1% to paid | K14: Day 45: 12 tools | L14: 12
B15: C — $3/day | C15: 8 | D15: 3 | E15: 1 | F15: =C15*C6+D15*C7+E15*C8 -> 89.88 | G15: =F15*12/365 -> 2.9549589 | H15: 3 | I15: =G15*(1-H15/100)+C9 -> 2.8663101 | J15: 1.5-3k visits/day via pSEO long-tail + Telegram channel | K15: Day 60: 25 tools | L15: 25
B16: D — $10/day | C16: 25 | D16: 8 | E16: 3 | F16: =C16*C6+D16*C7+E16*C8 -> 264.64 | G16: =F16*12/365 -> 8.7004932 | H16: 4 | I16: =G16*(1-H16/100)+C9 -> 8.3524734 | J16: 6-10k visits/day; churn <8%/mo; 2-4% free->paid on segment-fit tools | K16: Day 90: 45 tools | L16: 45
B17: E — $30/day | C17: 70 | D17: 25 | E17: 8 | F17: =C17*C6+D17*C7+E17*C8 -> 758.97 | G17: =F17*12/365 -> 24.952438 | H17: 5 | I17: =G17*(1-H17/100)+C9 -> 23.704816 | J17: 15-25k visits/day; email/Telegram list 5-10k; affiliate + AdsGram adds ~$7/day | K17: Month 5-6: 80+ tools | L17: 80
B19: MRR and $/day are live formulas — edit tier prices above to re-model. Fees = blended payment-rail cost (see Payment Rails). Scenario D/E assume affiliate + AdsGram top-ups beyond subscriptions (entered conservatively at $0 here; PDF report shows with +$1.5-7/day). Free->paid conversion assumptions are E3 and must be validated with real funnel data. Note: '工具-fit' = segment fit.

Sheet Payment Rails
B2: Payout Rails for BD Solo Founder (no bank/card) — verified 2026-09-02
B4: Rail | C4: Verdict | D4: Fees | E4: Min payout | F4: KYC | G4: Timeline | H4: Notes / risk | I4: Confidence
B5: Crypto affiliate USDT -> P2P -> bKash (Bybit/OKX) | C5: WORKS — cheapest chain | D5: ~1.4-2% total | E5: exchange min | F5: Exchange KYC + P2P counterparty | G5: hours-1 day | H5: Prefer Bybit/OKX P2P (0% fee, bKash/Nagad listed); Binance BD restricted Mar 2025; USDT/BDT rate 122-124 = +2-3.5% FX bonus; risk = MFS wallet freezes from many small P2P credits | I5: High (E2)
B6: Telegram Stars -> Fragment -> GRAM -> USDT -> P2P | C6: WORKS — native for TG products | D6: ~4-5% total | E6: 1,000 Stars (~$13) | F6: Fragment KYC mandatory (purchases since Nov 2024) | G6: 21-day hold + payout | H6: $0.013/Star payout rate; Toncoin renamed GRAM 1:1 (Jun 15, 2026) | I6: High (E2)
B7: AdsGram (TGA mini-app ads) | C7: WORKS — official TG ad network | D7: net-45 style | E7: $100 | F7: light | G7: monthly | H7: USDT-TON payouts; rewarded ads in Mini Apps | I7: Med-High (E2)
B8: Adsterra | C8: WORKS (crypto) | D8: rev-share | E8: $100 crypto (USDT-TRC20) | F8: email | G8: net-14/16 | H8: The famous $5 min is WebMoney/Paxum only, NOT crypto | I8: High (E2)
B9: Paddle -> Payoneer -> bKash | C9: WORKS — only mainstream SaaS checkout open to BD | D9: 3% + $1 (Payoneer->bKash min BDT 1000, cap BDT 250k/tx) | E9: Paddle $1,000 initial review bar | F9: Payoneer KYC (BD ID ok) | G9: weekly/2x-monthly | H9: Merchant-of-record solves sales tax; use when subscription volume justifies | I9: Med-High (E2)
B10: NOWPayments / BTCPay (accept rails) | C10: WORKS — inbound crypto acceptance | D10: 0.5-1.5% / 0% (self-host BTC-only) | E10: none-material | F10: email | G10: instant | H10: Accept USDT/BTC from customers; pair with P2P off-ramp | I10: Med (E2)
B11: Direct MTO remittance -> bKash (WU/MoneyGram/ACE/Taptap) | C11: WORKS but compliance-grey for client fees | D11: ~0.7% ATM cash-out; +2.5% govt incentive on remittance | E11: low | F11: ID per transfer | G11: minutes-hours | H11: Cheapest per-dollar; grey area for commercial receipts (FERA) — use for personal withdrawals, not client invoicing | I11: Med (E2/E3)
B12: Google AdSense | C12: BROKEN | D12: - | E12: $100 | F12: - | G12: - | H12: BD = wire-to-bank only; WU Quick Cash dead | I12: High (E2)
B13: Stripe / PayPal / Gumroad / Ko-fi / BMC / Patreon / Payhip / LemonSqueezy | C13: BROKEN | D13: - | E13: - | F13: - | G13: - | H13: All require BD bank or Stripe/PayPal payout country | I13: High (E2)
B14: Telegram channel ads rev-share (>=1k subs, 50%) | C14: UNVERIFIED for BD | D14: 50% share | E14: - | F14: - | G14: - | H14: Check in-app toggle; AdsGram is the fallback | I14: Low (E3)
B15: Bangladesh Bank legal note | C15: CONSTRAINT | D15: - | E15: - | F15: - | G15: - | H15: Crypto = grey zone (FERA 1947); practical risk = MFS freezes, not prosecution; keep P2P credits small & irregular | I15: Med (E2/E3)
B17: Full ledger with sources: research/payments.md. Strategy: start Stars + crypto (zero-setup), graduate to Paddle->Payoneer at scale for card-paying customers.

Sheet Free Infra
B2: $0 Infrastructure Stack — verified limits 2026-09-02
B4: Service | C4: Free-tier allowance | D4: Hard gotcha | E4: Role in FRAZIYM
B5: Cloudflare Workers | C5: 100k req/day, 10ms CPU | D5: CPU-time cap kills heavy compute; offload to client WASM | E5: API gateway + router + bots
B6: Cloudflare Pages | C6: unlimited bandwidth, 500 builds/mo | D6: — | E6: all static tool frontends
B7: Cloudflare D1 | C7: 5M reads/day, 100k writes/day, 5GB | D7: writes capped — batch/analytics offload | E7: users, usage ledger, tool registry
B8: Cloudflare R2 | C8: 10GB storage, 1M A/10M B ops, $0 egress | D8: — | E8: file staging for server-side jobs
B9: Cloudflare Queues + Cron | C9: Queues 10k ops/day (Feb 2026 change); Cron reliable | D9: — | E9: async jobs + schedulers
B10: Cloudflare KV | C10: 1k writes/day | D10: low-write only | E10: config/cache
B11: Turso / Neon | C11: Turso 500M reads/10M writes/5GB; Neon 100 CU-hr + 5-min autosuspend | D11: Neon autosuspend = cold starts; heartbeat cron mandatory | E11: DB depth beyond D1
B12: Supabase | C12: 2 projects, 500MB | D12: PAUSES after 7 days idle | E12: avoid as primary
B13: GitHub | C13: Actions 2,000 min/mo private (unlimited public); scheduled workflows BEST-EFFORT (60-day disable) | D13: never rely on GH cron for revenue jobs | E13: CI, OSS repo trust, Pages mirror
B14: Vercel Hobby | C14: 100GB, 1M invocations | D14: NON-COMMERCIAL terms; cron max 1/day | E14: avoid for the product itself
B15: Netlify | C15: 300 credits (~15GB) hard cap | D15: downgraded free tier | E15: dropped from stack
... B21: Domains | C21: DigitalPlat free (.dpdns.org/.us.kg); .xyz/.top $1-2 yr-1 | D21: custom domain REQUIRED for email/OAuth trust | E21: root domain + API subdomain
B23: Full 16-section verification with sources: research/infra.md. Architecture rule: anchor on Cloudflare; treat every free tier as disposable (failover-ready).

Sheet AI Providers
B2: Free AI Inference Providers — gateway design inputs 2026-09-02
B4: Provider | C4: Free allowance (verified) | D4: Card needed | E4: ToS / data notes | F4: Role in router
B5: Groq | C5: 30 RPM / 1K RPD / 8K TPM (gpt-oss + qwen); Whisper 2K RPD & 28.8k audio-sec/day | D5: No | E5: cached tokens excluded from limits | F5: PRIMARY anchor (speed + STT)
B6: OpenRouter :free | C6: 20 RPM, 50 RPD (1,000 RPD after $10 credit purchase) | D6: No | E6: free models = data-training pool | F6: SECONDARY + model variety
B7: Cloudflare Workers AI | C7: 10,000 Neurons/day | D7: No | E7: same stack as product = one bill, zero | F7: TERTIARY + embedding/small tasks
B8: SambaNova | C8: 20 RPM / 20 RPD / 200K TPD | D8: No | E8: — | F8: failover
B9: Mistral La Plateforme | C9: free tier exists (rate-limited) | D9: Phone verify | E9: — | F9: failover
B10: Cohere | C10: trial 1,000 calls/mo @20 RPM | D10: No | E10: trial key only | F10: embed/rank niche
B11: Gemini (AI Studio) | C11: free tier exists but ~20 RPD (Dec 2025 slash; no public table) | D11: No | E11: DATA USED FOR TRAINING = YES | F11: last-resort only
B12: Hugging Face Inference | C12: ~$0.10/mo free credits | D12: No | E12: — | F12: drop from router
B13: Cerebras / Together / GitHub Models | C13: ALL free tiers RETIRED (2025-07/2026-02/2026-07) | D13: - | E13: — | F13: removed
B14: Local (llama.cpp on Termux) | C14: 0-cost, device-bound | D14: - | E14: — | F14: offline dev-time fallback only
B16: Router policy: validate -> deterministic first -> cache -> small/local model -> free-cloud failover -> validate again. Pooled capacity ≈ 500-2,000 AI req/day at $0. Single account per provider (multi-accounting prohibited). Sources: research/ai-providers.md.

Sheet Review
B2: Cross-Validation (live checks)
B4: Check | C4: Expected | D4: Actual | E4: Status
B5: Opportunities row count | C5: 247 | D5: =COUNTA(Opportunities!C5:C251) -> 247 | E5: =IF(ROUND(C5,2)=ROUND(D5,2),"PASS","FAIL") -> PASS
B6: Top 50 row count | C6: 50 | D6: =COUNTA('Top 50'!C5:C54) -> 50 | E6: =IF(ROUND(C6,2)=ROUND(D6,2),"PASS","FAIL") -> PASS
B7: Clusters tool sum | C7: 247 | D7: =Clusters!C12 -> 247 | E7: =IF(ROUND(C7,2)=ROUND(D7,2),"PASS","FAIL") -> PASS
B8: Scenario B MRR ($) | C8: 24.96 | D8: ='Revenue Scenarios'!F14 -> 24.96 | E8: =IF(ROUND(C8,2)=ROUND(D8,2),"PASS","FAIL") -> PASS
B9: LTV+PRO+HOOK+GLUE sum | C9: 247 | D9: =COUNTIF(Opportunities!S5:S251,"LTV")+COUNTIF(Opportunities!S5:S251,"PRO")+COUNTIF(Opportunities!S5:S251,"HOOK")+COUNTIF(Opportunities!S5:S251,"GLUE") -> 247 | E9: =IF(ROUND(C9,2)=ROUND(D9,2),"PASS","FAIL") -> PASS
